Workbook
Name K_Deficiency: Soil!$C$96
Name K_Shortfall: Soil!$D$96
Name N_Deficiency: Soil!$C$94
Name N_Shortfall: Soil!$D$94
Name OM_Deficiency: Soil!$C$93
Name OM_Shortfall: Soil!$D$93
Name P_Deficiency: Soil!$C$95
Name P_Shortfall: Soil!$D$95
Name pH: Soil!$C$81
Name TextureIndex: 'C_N Ratio'!$A$1:$D$13

Sheet Soil
T5: Wheat
B6: Soil Data (The % of volumetric soil moisture content remaining at field capacity) | M6: USDA Scoring | Q6: Revised FC & WP | S6: Soil Characteristic | T6: Irrigation Cycles | V6: Optimal Level of Nutrients per Soil Type @ 15cm Soil Depth
B7: Texture | C7: Field Capacity | D7: Wilting Point | E7: Sand (%) | F7: Silt (%) | G7: Clay (%) | H7: TAW | I7: RAW | J7: Total Moisture Content | K7: Porosity % | L7: Saturation | M7: USDA Index | N7: EC_Factor | O7: BIAS | P7: Drainage | Q7: FC - Check | R7: WP - Check | S7: Irrigation Needs | T7: Minimum | U7: Maximum | V7: Nitrogen (N) | W7: Phosphorus (P) | X7: Potassium (K) | Y7: pH | Z7: EC | AA7: Moisture % | AB7: Threshold %
B8: Sand | C8: 11 | D8: 4 | E8: =U39 -> 92.5 | F8: =W39 -> 7.5 | G8: =Y39 -> 5 | H8: =C8-D8 -> 7 | I8: =H8*(AB8/100) -> 5.25 | J8: =(C8-(H8*AB8/100)) -> 5.75 | K8: =(1 - _xlfn.XLOOKUP( USDAClass[[#This Row],[Texture]], SoilSpec[Texture], SoilSpec[BD_Min (t/m³)] ) / _xlfn.XLOOKUP( USDAClass[[#This Row],[Texture]], SoilSpec[Texture], SoilSpec[Particle Density] ) ) * 100 -> 49.685535 | L8: =ROUND( USDAClass[[#This Row],[Field Capacity]] / USDAClass[[#This Row],[Porosity %]] * 100, 0 ) -> 22 | M8: 0 | N8: =ROUND(5+USDAClass[[#This Row],[Clay (%)]]/10,0) -> 6 | O8: =USDAClass[[#This Row],[USDA Index]]+1 -> 1 | P8: Rapid | Q8: =_xlfn.LET( _xlpm.total, E8 + F8 + G8, _xlpm.s, E8 / _xlpm.total, _xlpm.c, G8 / _xlpm.total, _xlpm.om, IF(ISNUMBER(Y2), Y2 / 100, 0), _xlpm.theta33, -0.251*_xlpm.s + 0.195*_xlpm.c + 0.011*_xlpm.om + 0.006*_xlpm.s*_xlpm.om - 0.027*_xlpm.c*_xlpm.om + 0.452*_xlpm.s*_xlpm.c + 0.299, MAX(0, MIN(100, _xlpm.theta33 * 100)) ) -> 10.612812 | R8: =_xlfn.LET( _xlpm.total, E8 + F8 + G8, _xlpm.s, E8 / _xlpm.total, _xlpm.c, G8 / _xlpm.total, _xlpm.om, IF(ISNUMBER(Y2), Y2 / 100, 0), _xlpm.theta1500, -0.024*_xlpm.s + 0.487*_xlpm.c + 0.006*_xlpm.om + 0.005*_xlpm.s*_xlpm.om - 0.013*_xlpm.c*_xlpm.om + 0.068*_xlpm.s*_xlpm.c + 0.031, MAX(0, MIN(100, _xlpm.theta1500 * 100)) ) -> 3.5900227 | S8: Frequent, Short Cycles | T8: 6 | U8: 8 | V8: =AVERAGE( VLOOKUP(B8,$B$24:$AF$35,2,FALSE), VLOOKUP(B8,$B$24:$AF$35,3,FALSE) ) -> 7 | W8: =AVERAGE( VLOOKUP($B8,$B$24:$AF$35,4,FALSE), VLOOKUP($B8,$B$24:$AF$35,5,FALSE) ) -> 7 | X8: =AVERAGE( VLOOKUP($B8,$B$24:$AF$35,6,FALSE), VLOOKUP($B8,$B$24:$AF$35,7,FALSE) ) -> 70 | Y8: =AVERAGE( VLOOKUP(B8,$B$24:$AF$35,10,FALSE), VLOOKUP(B8,$B$24:$AF$35,11,FALSE) ) -> 7.25 | Z8: =AVERAGE( VLOOKUP(B8,$B$24:$AF$35,8,FALSE), VLOOKUP(B8,$B$24:$AF$35,9,FALSE) ) -> 0.775 | AA8: =AVERAGE( VLOOKUP(B8,$B$24:$AF$35,12,FALSE), VLOOKUP(B8,$B$24:$AF$35,13,FALSE) ) -> 10 | AB8: 75
B9: Loamy Sand | C9: 18 | D9: 8 | E9: =U40 -> 80 | F9: =W40 -> 12.5 | G9: =Y40 -> 7.5 | H9: =C9-D9 -> 10 | I9: =H9*(AB9/100) -> 7.5 | J9: =(C9-(H9*AB9/100)) -> 10.5 | K9: =(1 - _xlfn.XLOOKUP( USDAClass[[#This Row],[Texture]], SoilSpec[Texture], SoilSpec[BD_Min (t/m³)] ) / _xlfn.XLOOKUP( USDAClass[[#This Row],[Texture]], SoilSpec[Texture], SoilSpec[Particle Density] ) ) * 100 -> 45.283019 | L9: =ROUND( USDAClass[[#This Row],[Field Capacity]] / USDAClass[[#This Row],[Porosity %]] * 100, 0 ) -> 40 | M9: 1 | N9: =ROUND(5+USDAClass[[#This Row],[Clay (%)]]/10,0) -> 6 | O9: =USDAClass[[#This Row],[USDA Index]]+1 -> 2 | P9: Good | Q9: =_xlfn.LET( _xlpm.total, E9 + F9 + G9, _xlpm.s, E9 / _xlpm.total, _xlpm.c, G9 / _xlpm.total, _xlpm.om, IF(ISNUMBER(Y3), Y3 / 100, 0), _xlpm.theta33, -0.251*_xlpm.s + 0.195*_xlpm.c + 0.011*_xlpm.om + 0.006*_xlpm.s*_xlpm.om - 0.027*_xlpm.c*_xlpm.om + 0.452*_xlpm.s*_xlpm.c + 0.299, MAX(0, MIN(100, _xlpm.theta33 * 100)) ) -> 13.9945 | R9: =_xlfn.LET( _xlpm.total, E9 + F9 + G9, _xlpm.s, E9 / _xlpm.total, _xlpm.c, G9 / _xlpm.total, _xlpm.om, IF(ISNUMBER(Y3), Y3 / 100, 0), _xlpm.theta1500, -0.024*_xlpm.s + 0.487*_xlpm.c + 0.006*_xlpm.om + 0.005*_xlpm.s*_xlpm.om - 0.013*_xlpm.c*_xlpm.om + 0.068*_xlpm.s*_xlpm.c + 0.031, MAX(0, MIN(100, _xlpm.theta1500 * 100)) ) -> 5.2405 | S9: Frequent, Moderate Cycles | T9: 5 | U9: 7 | V9: =AVERAGE( VLOOKUP(B9,$B$24:$AF$35,2,FALSE), VLOOKUP(B9,$B$24:$AF$35,3,FALSE) ) -> 9.5 | W9: =AVERAGE( VLOOKUP($B9,$B$24:$AF$35,4,FALSE), VLOOKUP($B9,$B$24:$AF$35,5,FALSE) ) -> 9 | X9: =AVERAGE( VLOOKUP($B9,$B$24:$AF$35,6,FALSE), VLOOKUP($B9,$B$24:$AF$35,7,FALSE) ) -> 90 | Y9: =AVERAGE( VLOOKUP(B9,$B$24:$AF$35,10,FALSE), VLOOKUP(B9,$B$24:$AF$35,11,FALSE) ) -> 7.15 | Z9: =AVERAGE( VLOOKUP(B9,$B$24:$AF$35,8,FALSE), VLOOKUP(B9,$B$24:$AF$35,9,FALSE) ) -> 1.025 | AA9: =AVERAGE( VLOOKUP(B9,$B$24:$AF$35,12,FALSE), VLOOKUP(B9,$B$24:$AF$35,13,FALSE) ) -> 14 | AB9: 75
B10: Sandy Loam | C10: 23 | D10: 10 | E10: =U41 -> 64 | F10: =W41 -> 25 | G10: =Y41 -> 10 | H10: =C10-D10 -> 13 | I10: =H10*(AB10/100) -> 9.1 | J10: =(C10-(H10*AB10/100)) -> 13.9 | K10: =(1 - _xlfn.XLOOKUP( USDAClass[[#This Row],[Texture]], SoilSpec[Texture], SoilSpec[BD_Min (t/m³)] ) / _xlfn.XLOOKUP( USDAClass[[#This Row],[Texture]], SoilSpec[Texture], SoilSpec[Particle Density] ) ) * 100 -> 44.730322 | L10: =ROUND( USDAClass[[#This Row],[Field Capacity]] / USDAClass[[#This Row],[Porosity %]] * 100, 0 ) -> 51 | M10: 2 | N10: =ROUND(5+USDAClass[[#This Row],[Clay (%)]]/10,0) -> 6 | O10: =USDAClass[[#This Row],[USDA Index]]+1 -> 3 | P10: Good | Q10: =_xlfn.LET( _xlpm.total, E10 + F10 + G10, _xlpm.s, E10 / _xlpm.total, _xlpm.c, G10 / _xlpm.total, _xlpm.om, IF(ISNUMBER(Y4), Y4 / 100, 0), _xlpm.theta33, -0.251*_xlpm.s + 0.195*_xlpm.c + 0.011*_xlpm.om + 0.006*_xlpm.s*_xlpm.om - 0.027*_xlpm.c*_xlpm.om + 0.452*_xlpm.s*_xlpm.c + 0.299, MAX(0, MIN(100, _xlpm.theta33 * 100)) ) -> 18.59497 | R10: =_xlfn.LET( _xlpm.total, E10 + F10 + G10, _xlpm.s, E10 / _xlpm.total, _xlpm.c, G10 / _xlpm.total, _xlpm.om, IF(ISNUMBER(Y4), Y4 / 100, 0), _xlpm.theta1500, -0.024*_xlpm.s + 0.487*_xlpm.c + 0.006*_xlpm.om + 0.005*_xlpm.s*_xlpm.om - 0.013*_xlpm.c*_xlpm.om + 0.068*_xlpm.s*_xlpm.c + 0.031, MAX(0, MIN(100, _xlpm.theta1500 * 100)) ) -> 6.9117131 | S10: Moderate frequency Cycles | T10: 4 | U10: 6 | V10: =AVERAGE( VLOOKUP(B10,$B$24:$AF$35,2,FALSE), VLOOKUP(B10,$B$24:$AF$35,3,FALSE) ) -> 13 | W10: =AVERAGE( VLOOKUP($B10,$B$24:$AF$35,4,FALSE), VLOOKUP($B10,$B$24:$AF$35,5,FALSE) ) -> 12 | X10: =AVERAGE( VLOOKUP($B10,$B$24:$AF$35,6,FALSE), VLOOKUP($B10,$B$24:$AF$35,7,FALSE) ) -> 120 | Y10: =AVERAGE( VLOOKUP(B10,$B$24:$AF$35,10,FALSE), VLOOKUP(B10,$B$24:$AF$35,11,FALSE) ) -> 7 | Z10: =AVERAGE( VLOOKUP(B10,$B$24:$AF$35,8,FALSE), VLOOKUP(B10,$B$24:$AF$35,9,FALSE) ) -> 1.3 | AA10: =AVERAGE( VLOOKUP(B10,$B$24:$AF$35,12,FALSE), VLOOKUP(B10,$B$24:$AF$35,13,FALSE) ) -> 17.5 | AB10: 70
B11: Loam | C11: 27 | D11: 12 | E11: =U42 -> 37.5 | F11: =W42 -> 39 | G11: =Y42 -> 17 | H11: =C11-D11 -> 15 | I11: =H11*(AB11/100) -> 9 | J11: =(C11-(H11*AB11/100)) -> 18 | K11: =(1 - _xlfn.XLOOKUP( USDAClass[[#This Row],[Texture]], SoilSpec[Texture], SoilSpec[BD_Min (t/m³)] ) / _xlfn.XLOOKUP( USDAClass[[#This Row],[Texture]], SoilSpec[Texture], SoilSpec[Particle Density] ) ) * 100 -> 51.568964 | L11: =ROUND( USDAClass[[#This Row],[Field Capacity]] / USDAClass[[#This Row],[Porosity %]] * 100, 0 ) -> 52 | M11: 3 | N11: =ROUND(5+USDAClass[[#This Row],[Clay (%)]]/10,0) -> 7 | O11: =USDAClass[[#This Row],[USDA Index]]+1 -> 4 | P11: Moderate | Q11: =_xlfn.LET( _xlpm.total, E11 + F11 + G11, _xlpm.s, E11 / _xlpm.total, _xlpm.c, G11 / _xlpm.total, _xlpm.om, IF(ISNUMBER(#REF!),#REF! / 100, 0), _xlpm.theta33, -0.251*_xlpm.s + 0.195*_xlpm.c + 0.011*_xlpm.om + 0.006*_xlpm.s*_xlpm.om - 0.027*_xlpm.c*_xlpm.om + 0.452*_xlpm.s*_xlpm.c + 0.299, MAX(0, MIN(100, _xlpm.theta33 * 100)) ) -> 26.674672 | R11: =_xlfn.LET( _xlpm.total, E11 + F11 + G11, _xlpm.s, E11 / _xlpm.total, _xlpm.c, G11 / _xlpm.total, _xlpm.om, IF(ISNUMBER(#REF!),#REF! / 100, 0), _xlpm.theta1500, -0.024*_xlpm.s + 0.487*_xlpm.c + 0.006*_xlpm.om + 0.005*_xlpm.s*_xlpm.om - 0.013*_xlpm.c*_xlpm.om + 0.068*_xlpm.s*_xlpm.c + 0.031, MAX(0, MIN(100, _xlpm.theta1500 * 100)) ) -> 11.487846 | S11: Balanced Frequency and Duration | T11: 3 | U11: 5 | V11: =AVERAGE( VLOOKUP(B11,$B$24:$AF$35,2,FALSE), VLOOKUP(B11,$B$24:$AF$35,3,FALSE) ) -> 16.5 | W11: =AVERAGE( VLOOKUP($B11,$B$24:$AF$35,4,FALSE), VLOOKUP($B11,$B$24:$AF$35,5,FALSE) ) -> 15 | X11: =AVERAGE( VLOOKUP($B11,$B$24:$AF$35,6,FALSE), VLOOKUP($B11,$B$24:$AF$35,7,FALSE) ) -> 155 | Y11: =AVERAGE( VLOOKUP(B11,$B$24:$AF$35,10,FALSE), VLOOKUP(B11,$B$24:$AF$35,11,FALSE) ) -> 6.85 | Z11: =AVERAGE( VLOOKUP(B11,$B$24:$AF$35,8,FALSE), VLOOKUP(B11,$B$24:$AF$35,9,FALSE) ) -> 1.55 | AA11: =AVERAGE( VLOOKUP(B11,$B$24:$AF$35,12,FALSE), VLOOKUP(B11,$B$24:$AF$35,13,FALSE) ) -> 22.5 | AB11: 60
B12: Silt Loam | C12: 28 | D12: 10 | E12: =U43 -> 25 | F12: =W43 -> 69 | G12: =Y43 -> 13.5 | H12: =C12-D12 -> 18 | I12: =H12*(AB12/100) -> 10.8 | J12: =(C12-(H12*AB12/100)) -> 17.2 | K12: =(1 - _xlfn.XLOOKUP( USDAClass[[#This Row],[Texture]], SoilSpec[Texture], SoilSpec[BD_Min (t/m³)] ) / _xlfn.XLOOKUP( USDAClass[[#This Row],[Texture]], SoilSpec[Texture], SoilSpec[Particle Density] ) ) * 100 -> 59.631417 | L12: =ROUND( USDAClass[[#This Row],[Field Capacity]] / USDAClass[[#This Row],[Porosity %]] * 100, 0 ) -> 47 | M12: 4 | N12: =ROUND(5+USDAClass[[#This Row],[Clay (%)]]/10,0) -> 6 | O12: =USDAClass[[#This Row],[USDA Index]]+1 -> 5 | P12: Moderate | Q12: =_xlfn.LET( _xlpm.total, E12 + F12 + G12, _xlpm.s, E12 / _xlpm.total, _xlpm.c, G12 / _xlpm.total, _xlpm.om, IF(ISNUMBER(#REF!),#REF! / 100, 0), _xlpm.theta33, -0.251*_xlpm.s + 0.195*_xlpm.c + 0.011*_xlpm.om + 0.006*_xlpm.s*_xlpm.om - 0.027*_xlpm.c*_xlpm.om + 0.452*_xlpm.s*_xlpm.c + 0.299, MAX(0, MIN(100, _xlpm.theta33 * 100)) ) -> 27.831693 | R12: =_xlfn.LET( _xlpm.total, E12 + F12 + G12, _xlpm.s, E12 / _xlpm.total, _xlpm.c, G12 / _xlpm.total, _xlpm.om, IF(ISNUMBER(#REF!),#REF! / 100, 0), _xlpm.theta1500, -0.024*_xlpm.s + 0.487*_xlpm.c + 0.006*_xlpm.om + 0.005*_xlpm.s*_xlpm.om - 0.013*_xlpm.c*_xlpm.om + 0.068*_xlpm.s*_xlpm.c + 0.031, MAX(0, MIN(100, _xlpm.theta1500 * 100)) ) -> 8.8562683 | S12: Less frequent, Longer Cycles | T12: 3 | U12: 4 | V12: =AVERAGE( VLOOKUP(B12,$B$24:$AF$35,2,FALSE), VLOOKUP(B12,$B$24:$AF$35,3,FALSE) ) -> 20 | W12: =AVERAGE( VLOOKUP($B12,$B$24:$AF$35,4,FALSE), VLOOKUP($B12,$B$24:$AF$35,5,FALSE) ) -> 18 | X12: =AVERAGE( VLOOKUP($B12,$B$24:$AF$35,6,FALSE), VLOOKUP($B12,$B$24:$AF$35,7,FALSE) ) -> 185 | Y12: =AVERAGE( VLOOKUP(B12,$B$24:$AF$35,10,FALSE), VLOOKUP(B12,$B$24:$AF$35,11,FALSE) ) -> 6.75 | Z12: =AVERAGE( VLOOKUP(B12,$B$24:$AF$35,8,FALSE), VLOOKUP(B12,$B$24:$AF$35,9,FALSE) ) -> 1.55 | AA12: =AVERAGE( VLOOKUP(B12,$B$24:$AF$35,12,FALSE), VLOOKUP(B12,$B$24:$AF$35,13,FALSE) ) -> 27.5 | AB12: 60
B13: Clay Loam | C13: 31 | D13: 17 | E13: =U44 -> 36 | F13: =W44 -> 36 | G13: =Y44 -> 29 | H13: =C13-D13 -> 14 | I13: =H13*(AB13/100) -> 8.4 | J13: =(C13-(H13*AB13/100)) -> 22.6 | K13: =(1 - _xlfn.XLOOKUP( USDAClass[[#This Row],[Texture]], SoilSpec[Texture], SoilSpec[BD_Min (t/m³)] ) / _xlfn.XLOOKUP( USDAClass[[#This Row],[Texture]], SoilSpec[Texture], SoilSpec[Particle Density] ) ) * 100 -> 58.901551 | L13: =ROUND( USDAClass[[#This Row],[Field Capacity]] / USDAClass[[#This Row],[Porosity %]] * 100, 0 ) -> 53 | M13: 7 | N13: =ROUND(5+USDAClass[[#This Row],[Clay (%)]]/10,0) -> 8 | O13: =USDAClass[[#This Row],[USDA Index]]+1 -> 8 | P13: Slow | Q13: =_xlfn.LET( _xlpm.total, E13 + F13 + G13, _xlpm.s, E13 / _xlpm.total, _xlpm.c, G13 / _xlpm.total, _xlpm.om, IF(ISNUMBER(#REF!),#REF! / 100, 0), _xlpm.theta33, -0.251*_xlpm.s + 0.195*_xlpm.c + 0.011*_xlpm.om + 0.006*_xlpm.s*_xlpm.om - 0.027*_xlpm.c*_xlpm.om + 0.452*_xlpm.s*_xlpm.c + 0.299, MAX(0, MIN(100, _xlpm.theta33 * 100)) ) -> 31.178375 | R13: =_xlfn.LET( _xlpm.total, E13 + F13 + G13, _xlpm.s, E13 / _xlpm.total, _xlpm.c, G13 / _xlpm.total, _xlpm.om, IF(ISNUMBER(#REF!),#REF! / 100, 0), _xlpm.theta1500, -0.024*_xlpm.s + 0.487*_xlpm.c + 0.006*_xlpm.om + 0.005*_xlpm.s*_xlpm.om - 0.013*_xlpm.c*_xlpm.om + 0.068*_xlpm.s*_xlpm.c + 0.031, MAX(0, MIN(100, _xlpm.theta1500 * 100)) ) -> 16.923655 | S13: Infrequent, Long Cycles | T13: 2 | U13: 4 | V13: =AVERAGE( VLOOKUP(B13,$B$24:$AF$35,2,FALSE), VLOOKUP(B13,$B$24:$AF$35,3,FALSE) ) -> 22.5 | W13: =AVERAGE( VLOOKUP($B13,$B$24:$AF$35,4,FALSE), VLOOKUP($B13,$B$24:$AF$35,5,FALSE) ) -> 20.5 | X13: =AVERAGE( VLOOKUP($B13,$B$24:$AF$35,6,FALSE), VLOOKUP($B13,$B$24:$AF$35,7,FALSE) ) -> 225 | Y13: =AVERAGE( VLOOKUP(B13,$B$24:$AF$35,10,FALSE), VLOOKUP(B13,$B$24:$AF$35,11,FALSE) ) -> 6.75 | Z13: =AVERAGE( VLOOKUP(B13,$B$24:$AF$35,8,FALSE), VLOOKUP(B13,$B$24:$AF$35,9,FALSE) ) -> 2.075 | AA13: =AVERAGE( VLOOKUP(B13,$B$24:$AF$35,12,FALSE), VLOOKUP(B13,$B$24:$AF$35,13,FALSE) ) -> 30 | AB13: 60
B14: Silt | C14: 30 | D14: 9 | E14: =U45 -> 10 | F14: =W45 -> 90 | G14: =Y45 -> 10 | H14: =C14-D14 -> 21 | I14: =H14*(AB14/100) -> 11.55 | J14: =(C14-(H14*AB14/100)) -> 18.45 | K14: =(1 - _xlfn.XLOOKUP( USDAClass[[#This Row],[Texture]], SoilSpec[Texture], SoilSpec[BD_Min (t/m³)] ) / _xlfn.XLOOKUP( USDAClass[[#This Row],[Texture]], SoilSpec[Texture], SoilSpec[Particle Density] ) ) * 100 -> 62.264151 | L14: =ROUND( USDAClass[[#This Row],[Field Capacity]] / USDAClass[[#This Row],[Porosity %]] * 100, 0 ) -> 48 | M14: 5 | N14: =ROUND(5+USDAClass[[#This Row],[Clay (%)]]/10,0) -> 6 | O14: =USDAClass[[#This Row],[USDA Index]]+1 -> 6 | P14: Moderate | Q14: =_xlfn.LET( _xlpm.total, E14 + F14 + G14, _xlpm.s, E14 / _xlpm.total, _xlpm.c, G14 / _xlpm.total, _xlpm.om, IF(ISNUMBER(#REF!),#REF! / 100, 0), _xlpm.theta33, -0.251*_xlpm.s + 0.195*_xlpm.c + 0.011*_xlpm.om + 0.006*_xlpm.s*_xlpm.om - 0.027*_xlpm.c*_xlpm.om + 0.452*_xlpm.s*_xlpm.c + 0.299, MAX(0, MIN(100, _xlpm.theta33 * 100)) ) -> 29.764463 | R14: =_xlfn.LET( _xlpm.total, E14 + F14 + G14, _xlpm.s, E14 / _xlpm.total, _xlpm.c, G14 / _xlpm.total, _xlpm.om, IF(ISNUMBER(#REF!),#REF! / 100, 0), _xlpm.theta1500, -0.024*_xlpm.s + 0.487*_xlpm.c + 0.006*_xlpm.om + 0.005*_xlpm.s*_xlpm.om - 0.013*_xlpm.c*_xlpm.om + 0.068*_xlpm.s*_xlpm.c + 0.031, MAX(0, MIN(100, _xlpm.theta1500 * 100)) ) -> 7.3652893 | S14: Moderate frequency Cycles | T14: 3 | U14: 4 | V14: =AVERAGE( VLOOKUP(B14,$B$24:$AF$35,2,FALSE), VLOOKUP(B14,$B$24:$AF$35,3,FALSE) ) -> 20 | W14: =AVERAGE( VLOOKUP($B14,$B$24:$AF$35,4,FALSE), VLOOKUP($B14,$B$24:$AF$35,5,FALSE) ) -> 18 | X14: =AVERAGE( VLOOKUP($B14,$B$24:$AF$35,6,FALSE), VLOOKUP($B14,$B$24:$AF$35,7,FALSE) ) -> 155 | Y14: =AVERAGE( VLOOKUP(B14,$B$24:$AF$35,10,FALSE), VLOOKUP(B14,$B$24:$AF$35,11,FALSE) ) -> 6.75 | Z14: =AVERAGE( VLOOKUP(B14,$B$24:$AF$35,8,FALSE), VLOOKUP(B14,$B$24:$AF$35,9,FALSE) ) -> 1.3 | AA14: =AVERAGE( VLOOKUP(B14,$B$24:$AF$35,12,FALSE), VLOOKUP(B14,$B$24:$AF$35,13,FALSE) ) -> 27.5 | AB14: 55
B15: Sandy Clay | C15: 33 | D15: 21 | E15: =U46 -> 65 | F15: =W46 -> 10 | G15: =Y46 -> 30 | H15: =C15-D15 -> 12 | I15: =H15*(AB15/100) -> 6.6 | J15: =(C15-(H15*AB15/100)) -> 26.4 | K15: =(1 - _xlfn.XLOOKUP( USDAClass[[#This Row],[Texture]], SoilSpec[Texture], SoilSpec[BD_Min (t/m³)] ) / _xlfn.XLOOKUP( USDAClass[[#This Row],[Texture]], SoilSpec[Texture], SoilSpec[Particle Density] ) ) * 100 -> 56.873315 | L15: =ROUND( USDAClass[[#This Row],[Field Capacity]] / USDAClass[[#This Row],[Porosity %]] * 100, 0 ) -> 58 | M15: 10 | N15: =ROUND(5+USDAClass[[#This Row],[Clay (%)]]/10,0) -> 8 | O15: =USDAClass[[#This Row],[USDA Index]]+1 -> 11 | P15: Moderate | Q15: =_xlfn.LET( _xlpm.total, E15 + F15 + G15, _xlpm.s, E15 / _xlpm.total, _xlpm.c, G15 / _xlpm.total, _xlpm.om, IF(ISNUMBER(#REF!),#REF! / 100, 0), _xlpm.theta33, -0.251*_xlpm.s + 0.195*_xlpm.c + 0.011*_xlpm.om + 0.006*_xlpm.s*_xlpm.om - 0.027*_xlpm.c*_xlpm.om + 0.452*_xlpm.s*_xlpm.c + 0.299, MAX(0, MIN(100, _xlpm.theta33 * 100)) ) -> 27.927891 | R15: =_xlfn.LET( _xlpm.total, E15 + F15 + G15, _xlpm.s, E15 / _xlpm.total, _xlpm.c, G15 / _xlpm.total, _xlpm.om, IF(ISNUMBER(#REF!),#REF! / 100, 0), _xlpm.theta1500, -0.024*_xlpm.s + 0.487*_xlpm.c + 0.006*_xlpm.om + 0.005*_xlpm.s*_xlpm.om - 0.013*_xlpm.c*_xlpm.om + 0.068*_xlpm.s*_xlpm.c + 0.031, MAX(0, MIN(100, _xlpm.theta1500 * 100)) ) -> 16.731293 | S15: Moderate frequency, Longer Cycles | T15: 3 | U15: 5 | V15: =AVERAGE( VLOOKUP(B15,$B$24:$AF$35,2,FALSE), VLOOKUP(B15,$B$24:$AF$35,3,FALSE) ) -> 16.5 | W15: =AVERAGE( VLOOKUP($B15,$B$24:$AF$35,4,FALSE), VLOOKUP($B15,$B$24:$AF$35,5,FALSE) ) -> 15 | X15: =AVERAGE( VLOOKUP($B15,$B$24:$AF$35,6,FALSE), VLOOKUP($B15,$B$24:$AF$35,7,FALSE) ) -> 190 | Y15: =AVERAGE( VLOOKUP(B15,$B$24:$AF$35,10,FALSE), VLOOKUP(B15,$B$24:$AF$35,11,FALSE) ) -> 7 | Z15: =AVERAGE( VLOOKUP(B15,$B$24:$AF$35,8,FALSE), VLOOKUP(B15,$B$24:$AF$35,9,FALSE) ) -> 1.55 | AA15: =AVERAGE( VLOOKUP(B15,$B$24:$AF$35,12,FALSE), VLOOKUP(B15,$B$24:$AF$35,13,FALSE) ) -> 22.5 | AB15: 55
B16: Silty Clay Loam | C16: 34 | D16: 17 | E16: =U47 -> 20 | F16: =W47 -> 50 | G16: =Y47 -> 33.5 | H16: =C16-D16 -> 17 | I16: =H16*(AB16/100) -> 8.5 | J16: =(C16-(H16*AB16/100)) -> 25.5 | K16: =(1 - _xlfn.XLOOKUP( USDAClass[[#This Row],[Texture]], SoilSpec[Texture], SoilSpec[BD_Min (t/m³)] ) / _xlfn.XLOOKUP( USDAClass[[#This Row],[Texture]], SoilSpec[Texture], SoilSpec[Particle Density] ) ) * 100 -> 56.248291 | L16: =ROUND( USDAClass[[#This Row],[Field Capacity]] / USDAClass[[#This Row],[Porosity %]] * 100, 0 ) -> 60 | M16: 8 | N16: =ROUND(5+USDAClass[[#This Row],[Clay (%)]]/10,0) -> 8 | O16: =USDAClass[[#This Row],[USDA Index]]+1 -> 9 | P16: Slow | Q16: =_xlfn.LET( _xlpm.total, E16 + F16 + G16, _xlpm.s, E16 / _xlpm.total, _xlpm.c, G16 / _xlpm.total, _xlpm.om, IF(ISNUMBER(#REF!),#REF! / 100, 0), _xlpm.theta33, -0.251*_xlpm.s + 0.195*_xlpm.c + 0.011*_xlpm.om + 0.006*_xlpm.s*_xlpm.om - 0.027*_xlpm.c*_xlpm.om + 0.452*_xlpm.s*_xlpm.c + 0.299, MAX(0, MIN(100, _xlpm.theta33 * 100)) ) -> 34.188396 | R16: =_xlfn.LET( _xlpm.total, E16 + F16 + G16, _xlpm.s, E16 / _xlpm.total, _xlpm.c, G16 / _xlpm.total, _xlpm.om, IF(ISNUMBER(#REF!),#REF! / 100, 0), _xlpm.theta1500, -0.024*_xlpm.s + 0.487*_xlpm.c + 0.006*_xlpm.om + 0.005*_xlpm.s*_xlpm.om - 0.013*_xlpm.c*_xlpm.om + 0.068*_xlpm.s*_xlpm.c + 0.031, MAX(0, MIN(100, _xlpm.theta1500 * 100)) ) -> 18.824341 | S16: Less frequent, Longer Cycles | T16: 2 | U16: 4 | V16: =AVERAGE( VLOOKUP(B16,$B$24:$AF$35,2,FALSE), VLOOKUP(B16,$B$24:$AF$35,3,FALSE) ) -> 26 | W16: =AVERAGE( VLOOKUP($B16,$B$24:$AF$35,4,FALSE), VLOOKUP($B16,$B$24:$AF$35,5,FALSE) ) -> 24 | X16: =AVERAGE( VLOOKUP($B16,$B$24:$AF$35,6,FALSE), VLOOKUP($B16,$B$24:$AF$35,7,FALSE) ) -> 260 | Y16: =AVERAGE( VLOOKUP(B16,$B$24:$AF$35,10,FALSE), VLOOKUP(B16,$B$24:$AF$35,11,FALSE) ) -> 6.75 | Z16: =AVERAGE( VLOOKUP(B16,$B$24:$AF$35,8,FALSE), VLOOKUP(B16,$B$24:$AF$35,9,FALSE) ) -> 2.1 | AA16: =AVERAGE( VLOOKUP(B16,$B$24:$AF$35,12,FALSE), VLOOKUP(B16,$B$24:$AF$35,13,FALSE) ) -> 35 | AB16: 50
B17: Silty Clay | C17: 38 | D17: 25 | E17: =U48 -> 10 | F17: =W48 -> 50 | G17: =Y48 -> 50 | H17: =C17-D17 -> 13 | I17: =H17*(AB17/100) -> 6.5 | J17: =(C17-(H17*AB17/100)) -> 31.5 | K17: =(1 - _xlfn.XLOOKUP( USDAClass[[#This Row],[Texture]], SoilSpec[Texture], SoilSpec[BD_Min (t/m³)] ) / _xlfn.XLOOKUP( USDAClass[[#This Row],[Texture]], SoilSpec[Texture], SoilSpec[Particle Density] ) ) * 100 -> 62.264151 | L17: =ROUND( USDAClass[[#This Row],[Field Capacity]] / USDAClass[[#This Row],[Porosity %]] * 100, 0 ) -> 61 | M17: 9 | N17: =ROUND(5+USDAClass[[#This Row],[Clay (%)]]/10,0) -> 10 | O17: =USDAClass[[#This Row],[USDA Index]]+1 -> 10 | P17: Very Slow | Q17: =_xlfn.LET( _xlpm.total, E17 + F17 + G17, _xlpm.s, E17 / _xlpm.total, _xlpm.c, G17 / _xlpm.total, _xlpm.om, IF(ISNUMBER(#REF!),#REF! / 100, 0), _xlpm.theta33, -0.251*_xlpm.s + 0.195*_xlpm.c + 0.011*_xlpm.om + 0.006*_xlpm.s*_xlpm.om - 0.027*_xlpm.c*_xlpm.om + 0.452*_xlpm.s*_xlpm.c + 0.299, MAX(0, MIN(100, _xlpm.theta33 * 100)) ) -> 38.349587 | R17: =_xlfn.LET( _xlpm.total, E17 + F17 + G17, _xlpm.s, E17 / _xlpm.total, _xlpm.c, G17 / _xlpm.total, _xlpm.om, IF(ISNUMBER(#REF!),#REF! / 100, 0), _xlpm.theta1500, -0.024*_xlpm.s + 0.487*_xlpm.c + 0.006*_xlpm.om + 0.005*_xlpm.s*_xlpm.om - 0.013*_xlpm.c*_xlpm.om + 0.068*_xlpm.s*_xlpm.c + 0.031, MAX(0, MIN(100, _xlpm.theta1500 * 100)) ) -> 25.299174 | S17: Infrequent, Long Cycles | T17: 2 | U17: 3 | V17: =AVERAGE( VLOOKUP(B17,$B$24:$AF$35,2,FALSE), VLOOKUP(B17,$B$24:$AF$35,3,FALSE) ) -> 30 | W17: =AVERAGE( VLOOKUP($B17,$B$24:$AF$35,4,FALSE), VLOOKUP($B17,$B$24:$AF$35,5,FALSE) ) -> 27.5 | X17: =AVERAGE( VLOOKUP($B17,$B$24:$AF$35,6,FALSE), VLOOKUP($B17,$B$24:$AF$35,7,FALSE) ) -> 300 | Y17: =AVERAGE( VLOOKUP(B17,$B$24:$AF$35,10,FALSE), VLOOKUP(B17,$B$24:$AF$35,11,FALSE) ) -> 6.75 | Z17: =AVERAGE( VLOOKUP(B17,$B$24:$AF$35,8,FALSE), VLOOKUP(B17,$B$24:$AF$35,9,FALSE) ) -> 2.35 | AA17: =AVERAGE( VLOOKUP(B17,$B$24:$AF$35,12,FALSE), VLOOKUP(B17,$B$24:$AF$35,13,FALSE) ) -> 35 | AB17: 50
B18: Clay | C18: 36 | D18: 24 | E18: =U49 -> 22.5 | F18: =W49 -> 22.5 | G18: =Y49 -> 70 | H18: =C18-D18 -> 12 | I18: =H18*(AB18/100) -> 5.4 | J18: =(C18-(H18*AB18/100)) -> 30.6 | K18: =(1 - _xlfn.XLOOKUP( USDAClass[[#This Row],[Texture]], SoilSpec[Texture], SoilSpec[BD_Min (t/m³)] ) / _xlfn.XLOOKUP( USDAClass[[#This Row],[Texture]], SoilSpec[Texture], SoilSpec[Particle Density] ) ) * 100 -> 65.545529 | L18: =ROUND( USDAClass[[#This Row],[Field Capacity]] / USDAClass[[#This Row],[Porosity %]] * 100, 0 ) -> 55 | M18: 11 | N18: =ROUND(5+USDAClass[[#This Row],[Clay (%)]]/10,0) -> 12 | O18: =USDAClass[[#This Row],[USDA Index]]+1 -> 12 | P18: Very Slow | Q18: =_xlfn.LET( _xlpm.total, E18 + F18 + G18, _xlpm.s, E18 / _xlpm.total, _xlpm.c, G18 / _xlpm.total, _xlpm.om, IF(ISNUMBER(#REF!),#REF! / 100, 0), _xlpm.theta33, -0.251*_xlpm.s + 0.195*_xlpm.c + 0.011*_xlpm.om + 0.006*_xlpm.s*_xlpm.om - 0.027*_xlpm.c*_xlpm.om + 0.452*_xlpm.s*_xlpm.c + 0.299, MAX(0, MIN(100, _xlpm.theta33 * 100)) ) -> 42.241682 | R18: =_xlfn.LET( _xlpm.total, E18 + F18 + G18, _xlpm.s, E18 / _xlpm.total, _xlpm.c, G18 / _xlpm.total, _xlpm.om, IF(ISNUMBER(#REF!),#REF! / 100, 0), _xlpm.theta1500, -0.024*_xlpm.s + 0.487*_xlpm.c + 0.006*_xlpm.om + 0.005*_xlpm.s*_xlpm.om - 0.013*_xlpm.c*_xlpm.om + 0.068*_xlpm.s*_xlpm.c + 0.031, MAX(0, MIN(100, _xlpm.theta1500 * 100)) ) -> 33.083743 | S18: Very Frequency, Very Long Cycles | T18: 2 | U18: 3 | V18: =AVERAGE( VLOOKUP(B18,$B$24:$AF$35,2,FALSE), VLOOKUP(B18,$B$24:$AF$35,3,FALSE) ) -> 32.5 | W18: =AVERAGE( VLOOKUP($B18,$B$24:$AF$35,4,FALSE), VLOOKUP($B18,$B$24:$AF$35,5,FALSE) ) -> 30 | X18: =AVERAGE( VLOOKUP($B18,$B$24:$AF$35,6,FALSE), VLOOKUP($B18,$B$24:$AF$35,7,FALSE) ) -> 325 | Y18: =AVERAGE( VLOOKUP(B18,$B$24:$AF$35,10,FALSE), VLOOKUP(B18,$B$24:$AF$35,11,FALSE) ) -> 6.75 | Z18: =AVERAGE( VLOOKUP(B18,$B$24:$AF$35,8,FALSE), VLOOKUP(B18,$B$24:$AF$35,9,FALSE) ) -> 2.6 | AA18: =AVERAGE( VLOOKUP(B18,$B$24:$AF$35,12,FALSE), VLOOKUP(B18,$B$24:$AF$35,13,FALSE) ) -> 37.5 | AB18: 45
B19: Sandy Clay Loam | C19: 27 | D19: 14 | E19: =U50 -> 62.5 | F19: =W50 -> 14 | G19: =Y50 -> 27.5 | H19: =C19-D19 -> 13 | I19: =H19*(AB19/100) -> 5.85 | J19: =(C19-(H19*AB19/100)) -> 21.15 | K19: =(1 - _xlfn.XLOOKUP( USDAClass[[#This Row],[Texture]], SoilSpec[Texture], SoilSpec[BD_Min (t/m³)] ) / _xlfn.XLOOKUP( USDAClass[[#This Row],[Texture]], SoilSpec[Texture], SoilSpec[Particle Density] ) ) * 100 -> 52.830189 | L19: =ROUND( USDAClass[[#This Row],[Field Capacity]] / USDAClass[[#This Row],[Porosity %]] * 100, 0 ) -> 51 | M19: 6 | N19: =ROUND(5+USDAClass[[#This Row],[Clay (%)]]/10,0) -> 8 | O19: =USDAClass[[#This Row],[USDA Index]]+1 -> 7 | P19: Moderate | Q19: =_xlfn.LET( _xlpm.total, E19 + F19 + G19, _xlpm.s, E19 / _xlpm.total, _xlpm.c, G19 / _xlpm.total, _xlpm.om, IF(ISNUMBER(#REF!),#REF! / 100, 0), _xlpm.theta33, -0.251*_xlpm.s + 0.195*_xlpm.c + 0.011*_xlpm.om + 0.006*_xlpm.s*_xlpm.om - 0.027*_xlpm.c*_xlpm.om + 0.452*_xlpm.s*_xlpm.c + 0.299, MAX(0, MIN(100, _xlpm.theta33 * 100)) ) -> 27.154761 | R19: =_xlfn.LET( _xlpm.total, E19 + F19 + G19, _xlpm.s, E19 / _xlpm.total, _xlpm.c, G19 / _xlpm.total, _xlpm.om, IF(ISNUMBER(#REF!),#REF! / 100, 0), _xlpm.theta1500, -0.024*_xlpm.s + 0.487*_xlpm.c + 0.006*_xlpm.om + 0.005*_xlpm.s*_xlpm.om - 0.013*_xlpm.c*_xlpm.om + 0.068*_xlpm.s*_xlpm.c + 0.031, MAX(0, MIN(100, _xlpm.theta1500 * 100)) ) -> 15.615671 | S19: Balanced Frequency and Duration | T19: 3 | U19: 5 | V19: =AVERAGE( VLOOKUP(B19,$B$24:$AF$35,2,FALSE), VLOOKUP(B19,$B$24:$AF$35,3,FALSE) ) -> 25 | W19: =AVERAGE( VLOOKUP($B19,$B$24:$AF$35,4,FALSE), VLOOKUP($B19,$B$24:$AF$35,5,FALSE) ) -> 17.5 | X19: =AVERAGE( VLOOKUP($B19,$B$24:$AF$35,6,FALSE), VLOOKUP($B19,$B$24:$AF$35,7,FALSE) ) -> 180 | Y19: =AVERAGE( VLOOKUP(B19,$B$24:$AF$35,10,FALSE), VLOOKUP(B19,$B$24:$AF$35,11,FALSE) ) -> 7 | Z19: =AVERAGE( VLOOKUP(B19,$B$24:$AF$35,8,FALSE), VLOOKUP(B19,$B$24:$AF$35,9,FALSE) ) -> 1.55 | AA19: =AVERAGE( VLOOKUP(B19,$B$24:$AF$35,12,FALSE), VLOOKUP(B19,$B$24:$AF$35,13,FALSE) ) -> 27.5 | AB19: 45
B22: Ranges | AE22: g/cm3
B23: Texture | C23: N_Min | D23: N_Max | E23: P_Min | F23: P_Max | G23: K_Min | H23: K_Max | I23: EC_Min | J23: EC_Max | K23: pH_Min | L23: pH_Max | M23: Moisture_Min | N23: Moisture_Max | O23: OM_Min | P23: OM_Max | Q23: Clay % | R23: CEC Typical (meq/100g) | S23: TF_Min | T23: TF_Max | U23: Nopt_Min | V23: Nopt_Max | W23: Popt_Min | X23: Popt_Max | Y23: Kopt_Min | Z23: Kopt_Max | AA23: SoilTemp_Min | AB23: SoilTemp_Max | AC23: BD_Min (t/m³) | AD23: BD_Max (t/m³) | AE23: Particle Density | AF23: Porosity_Min % | AG23: Porosity_Max % | AH23: Saturation_min | AI23: Saturation_max | AJ23: Sand_Min | AK23: Sand_Max | AL23: Silt_Min | AM23: Silt_Max | AN23: Clay_Min | AO23: Clay_Max
B24: Sand | C24: 2 | D24: 12 | E24: 2 | F24: 12 | G24: 20 | H24: 120 | I24: 0.05 | J24: 1.5 | K24: 6 | L24: 8.5 | M24: 5 | N24: 15 | O24: 0.1 | P24: 2 | Q24: =_xlfn.XLOOKUP( SoilSpec[[#This Row],[Texture]], USDAClass[Texture], USDAClass[Clay (%)], NA(), 0 ) -> 5 | R24: =ROUND(0.15 * SoilSpec[[#This Row],[Clay %]] + 1.5 * (SoilSpec[[#This Row],[OM_Min]] ), 2) -> 0.9 | S24: 0.05 | T24: 0.1 | U24: =ROUND(C24 + (D24-C24) * 0.3, 0) -> 5 | V24: =ROUND(C24 + (D24-C24) * 0.7, 0) -> 9 | W24: =ROUND(E24 + (F24-E24) * 0.3, 0) -> 5 | X24: =ROUND(E24 + (F24-E24) * 0.7, 0) -> 9 | Y24: =ROUND(G24 + (H24-G24) * 0.3, 0) -> 50 | Z24: =ROUND(G24 + (H24-G24) * 0.7, 0) -> 90 | AA24: 20 | AB24: 35 | AC24: 1.4 | AD24: 1.6 | AE24: =((E8*2.65)+(F8*2.65)+(G8*2.65))/100 -> 2.7825 | AF24: =(1-AD24/AE24)*100 -> 42.497754 | AG24: =(1-AC24/AE24)*100 -> 49.685535 | AH24: =(SoilSpec[[#This Row],[Moisture_Min]]/SoilSpec[[#This Row],[Porosity_Min %]])*100 -> 11.765328 | AI24: =SoilSpec[[#This Row],[Moisture_Max]]/SoilSpec[[#This Row],[Porosity_Max %]]*100 -> 30.189873 | AJ24: 85 | AK24: 100 | AL24: 0 | AM24: 15 | AN24: 0 | AO24: 10
B25: Loamy Sand | C25: 4 | D25: 15 | E25: 3 | F25: 15 | G25: 30 | H25: 150 | I25: 0.05 | J25: 2 | K25: 5.8 | L25: 8.5 | M25: 8 | N25: 20 | O25: 0.2 | P25: 2.5 | Q25: =_xlfn.XLOOKUP( SoilSpec[[#This Row],[Texture]], USDAClass[Texture], USDAClass[Clay (%)], NA(), 0 ) -> 7.5 | R25: =ROUND(0.15 * SoilSpec[[#This Row],[Clay %]] + 1.5 * (SoilSpec[[#This Row],[OM_Min]] ), 2) -> 1.43 | S25: 0.12 | T25: 0.16 | U25: =ROUND(C25 + (D25-C25) * 0.3, 0) -> 7 | V25: =ROUND(C25 + (D25-C25) * 0.7, 0) -> 12 | W25: =ROUND(E25 + (F25-E25) * 0.3, 0) -> 7 | X25: =ROUND(E25 + (F25-E25) * 0.7, 0) -> 11 | Y25: =ROUND(G25 + (H25-G25) * 0.3, 0) -> 66 | Z25: =ROUND(G25 + (H25-G25) * 0.7, 0) -> 114 | AA25: 22 | AB25: 36 | AC25: 1.45 | AD25: 1.65 | AE25: =((E9*2.65)+(F9*2.65)+(G9*2.65))/100 -> 2.65 | AF25: =(1-AD25/AE25)*100 -> 37.735849 | AG25: =(1-AC25/AE25)*100 -> 45.283019 | AH25: =(SoilSpec[[#This Row],[Moisture_Min]]/SoilSpec[[#This Row],[Porosity_Min %]])*100 -> 21.2 | AI25: =SoilSpec[[#This Row],[Moisture_Max]]/SoilSpec[[#This Row],[Porosity_Max %]]*100 -> 44.166667 | AJ25: 70 | AK25: 90 | AL25: 0 | AM25: 25 | AN25: 0 | AO25: 15
B26: Sandy Loam | C26: 6 | D26: 20 | E26: 4 | F26: 20 | G26: 40 | H26: 200 | I26: 0.1 | J26: 2.5 | K26: 5.5 | L26: 8.5 | M26: 10 | N26: 25 | O26: 0.3 | P26: 3 | Q26: =_xlfn.XLOOKUP( SoilSpec[[#This Row],[Texture]], USDAClass[Texture], USDAClass[Clay (%)], NA(), 0 ) -> 10 | R26: =ROUND(0.15 * SoilSpec[[#This Row],[Clay %]] + 1.5 * (SoilSpec[[#This Row],[OM_Min]] ), 2) -> 1.95 | S26: 0.18 | T26: 0.22 | U26: =ROUND(C26 + (D26-C26) * 0.3, 0) -> 10 | V26: =ROUND(C26 + (D26-C26) * 0.7, 0) -> 16 | W26: =ROUND(E26 + (F26-E26) * 0.3, 0) -> 9 | X26: =ROUND(E26 + (F26-E26) * 0.7, 0) -> 15 | Y26: =ROUND(G26 + (H26-G26) * 0.3, 0) -> 88 | Z26: =ROUND(G26 + (H26-G26) * 0.7, 0) -> 152 | AA26: 24 | AB26: 38 | AC26: 1.45 | AD26: 1.7 | AE26: =((E10*2.65)+(F10*2.65)+(G10*2.65))/100 -> 2.6235 | AF26: =(1-AD26/AE26)*100 -> 35.201067 | AG26: =(1-AC26/AE26)*100 -> 44.730322 | AH26: =(SoilSpec[[#This Row],[Moisture_Min]]/SoilSpec[[#This Row],[Porosity_Min %]])*100 -> 28.40823 | AI26: =SoilSpec[[#This Row],[Moisture_Max]]/SoilSpec[[#This Row],[Porosity_Max %]]*100 -> 55.890499 | AJ26: 43 | AK26: 85 | AL26: 0 | AM26: 50 | AN26: 0 | AO26: 20
B27: Loam | C27: 8 | D27: 25 | E27: 5 | F27: 25 | G27: 60 | H27: 250 | I27: 0.1 | J27: 3 | K27: 5.5 | L27: 8.2 | M27: 15 | N27: 30 | O27: 0.5 | P27: 4 | Q27: =_xlfn.XLOOKUP( SoilSpec[[#This Row],[Texture]], USDAClass[Texture], USDAClass[Clay (%)], NA(), 0 ) -> 17 | R27: =ROUND(0.15 * SoilSpec[[#This Row],[Clay %]] + 1.5 * (SoilSpec[[#This Row],[OM_Min]] ), 2) -> 3.3 | S27: 0.24 | T27: 0.3 | U27: =ROUND(C27 + (D27-C27) * 0.3, 0) -> 13 | V27: =ROUND(C27 + (D27-C27) * 0.7, 0) -> 20 | W27: =ROUND(E27 + (F27-E27) * 0.3, 0) -> 11 | X27: =ROUND(E27 + (F27-E27) * 0.7, 0) -> 19 | Y27: =ROUND(G27 + (H27-G27) * 0.3, 0) -> 117 | Z27: =ROUND(G27 + (H27-G27) * 0.7, 0) -> 193 | AA27: 24 | AB27: 38 | AC27: 1.2 | AD27: 1.4 | AE27: =((E11*2.65)+(F11*2.65)+(G11*2.65))/100 -> 2.47775 | AF27: =(1-AD27/AE27)*100 -> 43.497124 | AG27: =(1-AC27/AE27)*100 -> 51.568964 | AH27: =(SoilSpec[[#This Row],[Moisture_Min]]/SoilSpec[[#This Row],[Porosity_Min %]])*100 -> 34.485038 | AI27: =SoilSpec[[#This Row],[Moisture_Max]]/SoilSpec[[#This Row],[Porosity_Max %]]*100 -> 58.174526 | AJ27: 23 | AK27: 52 | AL27: 28 | AM27: 50 | AN27: 7 | AO27: 27
B28: Silt Loam | C28: 10 | D28: 30 | E28: 6 | F28: 30 | G28: 70 | H28: 300 | I28: 0.1 | J28: 3 | K28: 5.5 | L28: 8 | M28: 20 | N28: 35 | O28: 0.6 | P28: 4.5 | Q28: =_xlfn.XLOOKUP( SoilSpec[[#This Row],[Texture]], USDAClass[Texture], USDAClass[Clay (%)], NA(), 0 ) -> 13.5 | R28: =ROUND(0.15 * SoilSpec[[#This Row],[Clay %]] + 1.5 * (SoilSpec[[#This Row],[OM_Min]] ), 2) -> 2.93 | S28: 0.3 | T28: 0.38 | U28: =ROUND(C28 + (D28-C28) * 0.3, 0) -> 16 | V28: =ROUND(C28 + (D28-C28) * 0.7, 0) -> 24 | W28: =ROUND(E28 + (F28-E28) * 0.3, 0) -> 13 | X28: =ROUND(E28 + (F28-E28) * 0.7, 0) -> 23 | Y28: =ROUND(G28 + (H28-G28) * 0.3, 0) -> 139 | Z28: =ROUND(G28 + (H28-G28) * 0.7, 0) -> 231 | AA28: 24 | AB28: 38 | AC28: 1.15 | AD28: 1.35 | AE28: =((E12*2.65)+(F12*2.65)+(G12*2.65))/100 -> 2.84875 | AF28: =(1-AD28/AE28)*100 -> 52.610794 | AG28: =(1-AC28/AE28)*100 -> 59.631417 | AH28: =(SoilSpec[[#This Row],[Moisture_Min]]/SoilSpec[[#This Row],[Porosity_Min %]])*100 -> 38.015013 | AI28: =SoilSpec[[#This Row],[Moisture_Max]]/SoilSpec[[#This Row],[Porosity_Max %]]*100 -> 58.693893 | AJ28: 0 | AK28: 50 | AL28: 50 | AM28: 88 | AN28: 0 | AO28: 27
B29: Clay Loam | C29: 10 | D29: 35 | E29: 6 | F29: 35 | G29: 100 | H29: 350 | I29: 0.15 | J29: 4 | K29: 5 | L29: 8.5 | M29: 20 | N29: 40 | O29: 0.8 | P29: 5 | Q29: =_xlfn.XLOOKUP( SoilSpec[[#This Row],[Texture]], USDAClass[Texture], USDAClass[Clay (%)], NA(), 0 ) -> 29 | R29: =ROUND(0.15 * SoilSpec[[#This Row],[Clay %]] + 1.5 * (SoilSpec[[#This Row],[OM_Min]] ), 2) -> 5.55 | S29: 0.38 | T29: 0.45 | U29: =ROUND(C29 + (D29-C29) * 0.3, 0) -> 18 | V29: =ROUND(C29 + (D29-C29) * 0.7, 0) -> 28 | W29: =ROUND(E29 + (F29-E29) * 0.3, 0) -> 15 | X29: =ROUND(E29 + (F29-E29) * 0.7, 0) -> 26 | Y29: =ROUND(G29 + (H29-G29) * 0.3, 0) -> 175 | Z29: =ROUND(G29 + (H29-G29) * 0.7, 0) -> 275 | AA29: 23 | AB29: 36 | AC29: 1.1 | AD29: 1.3 | AE29: =((E13*2.65)+(F13*2.65)+(G13*2.65))/100 -> 2.6765 | AF29: =(1-AD29/AE29)*100 -> 51.429105 | AG29: =(1-AC29/AE29)*100 -> 58.901551 | AH29: =(SoilSpec[[#This Row],[Moisture_Min]]/SoilSpec[[#This Row],[Porosity_Min %]])*100 -> 38.888485 | AI29: =SoilSpec[[#This Row],[Moisture_Max]]/SoilSpec[[#This Row],[Porosity_Max %]]*100 -> 67.909927 | AJ29: 24 | AK29: 48 | AL29: 24 | AM29: 48 | AN29: 20 | AO29: 38
B30: Silt | C30: 10 | D30: 30 | E30: 6 | F30: 30 | G30: 60 | H30: 250 | I30: 0.1 | J30: 2.5 | K30: 5.5 | L30: 8 | M30: 20 | N30: 35 | O30: 0.6 | P30: 4 | Q30: =_xlfn.XLOOKUP( SoilSpec[[#This Row],[Texture]], USDAClass[Texture], USDAClass[Clay (%)], NA(), 0 ) -> 10 | R30: =ROUND(0.15 * SoilSpec[[#This Row],[Clay %]] + 1.5 * (SoilSpec[[#This Row],[OM_Min]] ), 2) -> 2.4 | S30: 0.4 | T30: 0.48 | U30: =ROUND(C30 + (D30-C30) * 0.3, 0) -> 16 | V30: =ROUND(C30 + (D30-C30) * 0.7, 0) -> 24 | W30: =ROUND(E30 + (F30-E30) * 0.3, 0) -> 13 | X30: =ROUND(E30 + (F30-E30) * 0.7, 0) -> 23 | Y30: =ROUND(G30 + (H30-G30) * 0.3, 0) -> 117 | Z30: =ROUND(G30 + (H30-G30) * 0.7, 0) -> 193 | AA30: 23 | AB30: 36 | AC30: 1.1 | AD30: 1.25 | AE30: =((E14*2.65)+(F14*2.65)+(G14*2.65))/100 -> 2.915 | AF30: =(1-AD30/AE30)*100 -> 57.118353 | AG30: =(1-AC30/AE30)*100 -> 62.264151 | AH30: =(SoilSpec[[#This Row],[Moisture_Min]]/SoilSpec[[#This Row],[Porosity_Min %]])*100 -> 35.015015 | AI30: =SoilSpec[[#This Row],[Moisture_Max]]/SoilSpec[[#This Row],[Porosity_Max %]]*100 -> 56.212121 | AJ30: 0 | AK30: 20 | AL30: 80 | AM30: 100 | AN30: 0 | AO30: 20
B31: Sandy Clay | C31: 8 | D31: 25 | E31: 5 | F31: 25 | G31: 80 | H31: 300 | I31: 0.1 | J31: 3 | K31: 5.5 | L31: 8.5 | M31: 15 | N31: 30 | O31: 0.5 | P31: 3.5 | Q31: =_xlfn.XLOOKUP( SoilSpec[[#This Row],[Texture]], USDAClass[Texture], USDAClass[Clay (%)], NA(), 0 ) -> 30 | R31: =ROUND(0.15 * SoilSpec[[#This Row],[Clay %]] + 1.5 * (SoilSpec[[#This Row],[OM_Min]] ), 2) -> 5.25 | S31: 0.5 | T31: 0.58 | U31: =ROUND(C31 + (D31-C31) * 0.3, 0) -> 13 | V31: =ROUND(C31 + (D31-C31) * 0.7, 0) -> 20 | W31: =ROUND(E31 + (F31-E31) * 0.3, 0) -> 11 | X31: =ROUND(E31 + (F31-E31) * 0.7, 0) -> 19 | Y31: =ROUND(G31 + (H31-G31) * 0.3, 0) -> 146 | Z31: =ROUND(G31 + (H31-G31) * 0.7, 0) -> 234 | AA31: 24 | AB31: 38 | AC31: 1.2 | AD31: 1.6 | AE31: =((E15*2.65)+(F15*2.65)+(G15*2.65))/100 -> 2.7825 | AF31: =(1-AD31/AE31)*100 -> 42.497754 | AG31: =(1-AC31/AE31)*100 -> 56.873315 | AH31: =(SoilSpec[[#This Row],[Moisture_Min]]/SoilSpec[[#This Row],[Porosity_Min %]])*100 -> 35.295983 | AI31: =SoilSpec[[#This Row],[Moisture_Max]]/SoilSpec[[#This Row],[Porosity_Max %]]*100 -> 52.748815 | AJ31: 45 | AK31: 85 | AL31: 0 | AM31: 20 | AN31: 20 | AO31: 40
B32: Silty Clay Loam | C32: 12 | D32: 40 | E32: 8 | F32: 40 | G32: 120 | H32: 400 | I32: 0.2 | J32: 4 | K32: 5 | L32: 8.5 | M32: 25 | N32: 45 | O32: 1 | P32: 5 | Q32: =_xlfn.XLOOKUP( SoilSpec[[#This Row],[Texture]], USDAClass[Texture], USDAClass[Clay (%)], NA(), 0 ) -> 33.5 | R32: =ROUND(0.15 * SoilSpec[[#This Row],[Clay %]] + 1.5 * (SoilSpec[[#This Row],[OM_Min]] ), 2) -> 6.53 | S32: 0.55 | T32: 0.62 | U32: =ROUND(C32 + (D32-C32) * 0.3, 0) -> 20 | V32: =ROUND(C32 + (D32-C32) * 0.7, 0) -> 32 | W32: =ROUND(E32 + (F32-E32) * 0.3, 0) -> 18 | X32: =ROUND(E32 + (F32-E32) * 0.7, 0) -> 30 | Y32: =ROUND(G32 + (H32-G32) * 0.3, 0) -> 204 | Z32: =ROUND(G32 + (H32-G32) * 0.7, 0) -> 316 | AA32: 23 | AB32: 36 | AC32: 1.2 | AD32: 1.4 | AE32: =((E16*2.65)+(F16*2.65)+(G16*2.65))/100 -> 2.74275 | AF32: =(1-AD32/AE32)*100 -> 48.956339 | AG32: =(1-AC32/AE32)*100 -> 56.248291 | AH32: =(SoilSpec[[#This Row],[Moisture_Min]]/SoilSpec[[#This Row],[Porosity_Min %]])*100 -> 51.06591 | AI32: =SoilSpec[[#This Row],[Moisture_Max]]/SoilSpec[[#This Row],[Porosity_Max %]]*100 -> 80.002431 | AJ32: 0 | AK32: 40 | AL32: 40 | AM32: 60 | AN32: 27 | AO32: 40
B33: Silty Clay | C33: 15 | D33: 45 | E33: 10 | F33: 45 | G33: 150 | H33: 450 | I33: 0.2 | J33: 4.5 | K33: 5 | L33: 8.5 | M33: 25 | N33: 45 | O33: 1 | P33: 5 | Q33: =_xlfn.XLOOKUP( SoilSpec[[#This Row],[Texture]], USDAClass[Texture], USDAClass[Clay (%)], NA(), 0 ) -> 50 | R33: =ROUND(0.15 * SoilSpec[[#This Row],[Clay %]] + 1.5 * (SoilSpec[[#This Row],[OM_Min]] ), 2) -> 9 | S33: 0.6 | T33: 0.66 | U33: =ROUND(C33 + (D33-C33) * 0.3, 0) -> 24 | V33: =ROUND(C33 + (D33-C33) * 0.7, 0) -> 36 | W33: =ROUND(E33 + (F33-E33) * 0.3, 0) -> 21 | X33: =ROUND(E33 + (F33-E33) * 0.7, 0) -> 35 | Y33: =ROUND(G33 + (H33-G33) * 0.3, 0) -> 240 | Z33: =ROUND(G33 + (H33-G33) * 0.7, 0) -> 360 | AA33: 22 | AB33: 36 | AC33: 1.1 | AD33: 1.3 | AE33: =((E17*2.65)+(F17*2.65)+(G17*2.65))/100 -> 2.915 | AF33: =(1-AD33/AE33)*100 -> 55.403087 | AG33: =(1-AC33/AE33)*100 -> 62.264151 | AH33: =(SoilSpec[[#This Row],[Moisture_Min]]/SoilSpec[[#This Row],[Porosity_Min %]])*100 -> 45.123839 | AI33: =SoilSpec[[#This Row],[Moisture_Max]]/SoilSpec[[#This Row],[Porosity_Max %]]*100 -> 72.272727 | AJ33: 0 | AK33: 20 | AL33: 40 | AM33: 60 | AN33: 40 | AO33: 60
B34: Clay | C34: 15 | D34: 50 | E34: 10 | F34: 50 | G34: 150 | H34: 500 | I34: 0.2 | J34: 5 | K34: 5 | L34: 8.5 | M34: 25 | N34: 50 | O34: 1 | P34: 6 | Q34: =_xlfn.XLOOKUP( SoilSpec[[#This Row],[Texture]], USDAClass[Texture], USDAClass[Clay (%)], NA(), 0 ) -> 70 | R34: =ROUND(0.15 * SoilSpec[[#This Row],[Clay %]] + 1.5 * (SoilSpec[[#This Row],[OM_Min]] ), 2) -> 12 | S34: 0.65 | T34: 0.72 | U34: =ROUND(C34 + (D34-C34) * 0.3, 0) -> 26 | V34: =ROUND(C34 + (D34-C34) * 0.7, 0) -> 40 | W34: =ROUND(E34 + (F34-E34) * 0.3, 0) -> 22 | X34: =ROUND(E34 + (F34-E34) * 0.7, 0) -> 38 | Y34: =ROUND(G34 + (H34-G34) * 0.3, 0) -> 255 | Z34: =ROUND(G34 + (H34-G34) * 0.7, 0) -> 395 | AA34: 20 | AB34: 34 | AC34: 1.05 | AD34: 1.3 | AE34: =((E18*2.65)+(F18*2.65)+(G18*2.65))/100 -> 3.0475 | AF34: =(1-AD34/AE34)*100 -> 57.342084 | AG34: =(1-AC34/AE34)*100 -> 65.545529 | AH34: =(SoilSpec[[#This Row],[Moisture_Min]]/SoilSpec[[#This Row],[Porosity_Min %]])*100 -> 43.597997 | AI34: =SoilSpec[[#This Row],[Moisture_Max]]/SoilSpec[[#This Row],[Porosity_Max %]]*100 -> 76.282854 | AJ34: 0 | AK34: 45 | AL34: 0 | AM34: 45 | AN34: 40 | AO34: 100
B35: Sandy Clay Loam | C35: 18 | D35: 32 | E35: 10 | F35: 25 | G35: 120 | H35: 240 | I35: 0.1 | J35: 3 | K35: 5.5 | L35: 8.5 | M35: 20 | N35: 35 | O35: 1 | P35: 4 | Q35: =_xlfn.XLOOKUP( SoilSpec[[#This Row],[Texture]], USDAClass[Texture], USDAClass[Clay (%)], NA(), 0 ) -> 27.5 | R35: =ROUND(0.15 * SoilSpec[[#This Row],[Clay %]] + 1.5 * (SoilSpec[[#This Row],[OM_Min]] ), 2) -> 5.63 | S35: 0.58 | T35: 0.66 | U35: =ROUND(C35 + (D35-C35) * 0.3, 0) -> 22 | V35: =ROUND(C35 + (D35-C35) * 0.7, 0) -> 28 | W35: =ROUND(E35 + (F35-E35) * 0.3, 0) -> 15 | X35: =ROUND(E35 + (F35-E35) * 0.7, 0) -> 21 | Y35: =ROUND(G35 + (H35-G35) * 0.3, 0) -> 156 | Z35: =ROUND(G35 + (H35-G35) * 0.7, 0) -> 204 | AA35: 26 | AB35: 40 | AC35: 1.3 | AD35: 1.55 | AE35: =((E19*2.65)+(F19*2.65)+(G19*2.65))/100 -> 2.756 | AF35: =(1-AD35/AE35)*100 -> 43.759071 | AG35: =(1-AC35/AE35)*100 -> 52.830189 | AH35: =(SoilSpec[[#This Row],[Moisture_Min]]/SoilSpec[[#This Row],[Porosity_Min %]])*100 -> 45.704809 | AI35: =SoilSpec[[#This Row],[Moisture_Max]]/SoilSpec[[#This Row],[Porosity_Max %]]*100 -> 66.25 | AJ35: 45 | AK35: 80 | AL35: 0 | AM35: 28 | AN35: 20 | AO35: 35
B37: Texture Calibration
B38: Texture | C38: N_Mean | D38: N_StdDev | E38: P_Mean | F38: P_StdDev | G38: K_Mean | H38: K_StdDev | I38: EC_Mean | J38: EC_StdDev | K38: pH_Mean | L38: pH_StdDev | M38: Moisture_Mean | N38: Moisture_StdDev | O38: Temp_Mean | P38: Temp_StdDev | Q38: TF_Center | R38: TF_StdDev | S38: OM_Mean | T38: OM_StdDev | U38: Sand_Mean | V38: Sand_StdDev | W38: Silt_Mean | X38: Silt_StdDev | Y38: Clay_Mean | Z38: Clay_StdDev | AA38: Euclidean Distance | AB38: Confidence | AC38: BandScore | AD38: NormDist | AE38: FinalScore
B39: Sand | C39: =(C24+D24)/2 -> 7 | D39: =(D24-C24)/6 -> 1.6666667 | E39: =(E24+F24)/2 -> 7 | F39: =(F24-E24)/6 -> 1.6666667 | G39: =(G24+H24)/2 -> 70 | H39: =(H24-G24)/6 -> 16.666667 | I39: =(I24+J24)/2 -> 0.775 | J39: =(J24-I24)/6 -> 0.24166667 | K39: =(K24+L24)/2 -> 7.25 | L39: =(L24-K24)/6 -> 0.41666667 | M39: =(M24+N24)/2 -> 10 | N39: =(N24-M24)/6 -> 1.6666667 | O39: =(AA24+AB24)/2 -> 27.5 | P39: =(AB24-AA24)/6 -> 2.5 | Q39: =(S24+T24)/2 -> 0.075 | R39: =(T24-S24)/4 -> 0.0125 | S39: =AVERAGE(O24:P24) -> 1.05 | T39: =_xlfn.STDEV.S(O24:P24) -> 1.3435029 | U39: =AVERAGE( _xlfn.XLOOKUP(TextureCal[[#This Row],[Texture]], SoilSpec[Texture], SoilSpec[Sand_Min]), _xlfn.XLOOKUP(TextureCal[[#This Row],[Texture]], SoilSpec[Texture], SoilSpec[Sand_Max]) ) -> 92.5 | V39: {=IFERROR(_xlfn.STDEV.S(_xlfn._xlws.FILTER(Soil_Samples[Sand], Soil_Samples[Texture]=TextureCal[[#This Row],[Texture]])),0)} -> 0 | W39: =AVERAGE( _xlfn.XLOOKUP(TextureCal[[#This Row],[Texture]], SoilSpec[Texture], SoilSpec[Silt_Min]), _xlfn.XLOOKUP(TextureCal[[#This Row],[Texture]], SoilSpec[Texture], SoilSpec[Silt_Max]) ) -> 7.5 | X39: {=IFERROR(_xlfn.STDEV.S(_xlfn._xlws.FILTER(Soil_Samples[Silt], Soil_Samples[Texture]=TextureCal[[#This Row],[Texture]])),0)} -> 0 | Y39: =AVERAGE( _xlfn.XLOOKUP(TextureCal[[#This Row],[Texture]], SoilSpec[Texture], SoilSpec[Clay_Min]), _xlfn.XLOOKUP(TextureCal[[#This Row],[Texture]], SoilSpec[Texture], SoilSpec[Clay_Max]) ) -> 5 | Z39: {=IFERROR(_xlfn.STDEV.S(_xlfn._xlws.FILTER(Soil_Samples[Clay], Soil_Samples[Texture]=TextureCal[[#This Row],[Texture]])),0)} -> 0 | AA39: {=_xlfn.LET( _xlpm.vals, _xlfn.HSTACK( $C$72, $C$73, $C$74, $C$80, pH, $C$76, $C$75, $C$79, $C$77 ), _xlpm.means, _xlfn.HSTACK( TextureCal[[#This Row],[N_Mean]], TextureCal[[#This Row],[P_Mean]], TextureCal[[#This Row],[K_Mean]], TextureCal[[#This Row],[EC_Mean]], TextureCal[[#This Row],[pH_Mean]], TextureCal[[#This Row],[Moisture_Mean]], TextureCal[[#This Row],[Temp_Mean]], TextureCal[[#This Row],[TF_Center]], TextureCal[[#This Row],[OM_Mean]] ), _xlpm.stds, _xlfn.HSTACK( TextureCal[[#This Row],[N_StdDev]], TextureCal[[#This Row],[P_StdDev]], TextureCal[[#This Row],[K_StdDev]], TextureCal[[#This Row],[EC_StdDev]], TextureCal[[#This Row],[pH_StdDev]], TextureCal[[#This Row],[Moisture_StdDev]], TextureCal[[#This Row],[Temp_StdDev]], TextureCal[[#This Row],[TF_StdDev]], TextureCal[[#This Row],[OM_StdDev]] ), SQRT(SUM(((_xlpm.vals - _xlpm.means) / _xlpm.stds)^2)) )} -> 8.0420646 | AB39: =1 - ( TextureCal[[#This Row],[Euclidean Distance]] - MIN(TextureCal[Euclidean Distance]) ) / ( MAX(TextureCal[Euclidean Distance]) - MIN(TextureCal[Euclidean Distance]) ) -> 1 | AC39: {=_xlfn.LET( _xlpm.vals, _xlfn.HSTACK($C$72,$C$73,$C$74,$C$80,$C$81,$C$76,$C$77,$C$79,$C$75), _xlpm.mins, _xlfn.HSTACK(SoilSpec[N_Min],SoilSpec[P_Min],SoilSpec[K_Min], SoilSpec[EC_Min],SoilSpec[pH_Min],SoilSpec[Moisture_Min], SoilSpec[OM_Min],SoilSpec[TF_Min],SoilSpec[SoilTemp_Min]), _xlpm.maxs, _xlfn.HSTACK(SoilSpec[N_Max],SoilSpec[P_Max],SoilSpec[K_Max], SoilSpec[EC_Max],SoilSpec[pH_Max],SoilSpec[Moisture_Max], SoilSpec[OM_Max],SoilSpec[TF_Max],SoilSpec[SoilTemp_Max]), _xlpm.idx, ROW()-ROW(TextureCal[#Headers]), SUM( (_xlpm.vals >= INDEX(_xlpm.mins, _xlpm.idx)) * (_xlpm.vals <= INDEX(_xlpm.maxs, _xlpm.idx)) ) )} -> 7 | AD39: =1 - ( TextureCal[[#This Row],[Euclidean Distance]] - MIN(TextureCal[Euclidean Distance]) ) / ( MAX(TextureCal[Euclidean Distance]) - MIN(TextureCal[Euclidean Distance]) ) -> 1 | AE39: =(TextureCal[[#This Row],[BandScore]] / 9) * 0.6 + TextureCal[[#This Row],[NormDist]] * 0.4 -> 0.86666667
B40: Loamy Sand | C40: =(C25+D25)/2 -> 9.5 | D40: =(D25-C25)/6 -> 1.8333333 | E40: =(E25+F25)/2 -> 9 | F40: =(F25-E25)/6 -> 2 | G40: =(G25+H25)/2 -> 90 | H40: =(H25-G25)/6 -> 20 | I40: =(I25+J25)/2 -> 1.025 | J40: =(J25-I25)/6 -> 0.325 | K40: =(K25+L25)/2 -> 7.15 | L40: =(L25-K25)/6 -> 0.45 | M40: =(M25+N25)/2 -> 14 | N40: =(N25-M25)/6 -> 2 | O40: =(AA25+AB25)/2 -> 29 | P40: =(AB25-AA25)/6 -> 2.3333333 | Q40: =(S25+T25)/2 -> 0.14 | R40: =(T25-S25)/4 -> 0.01 | S40: =AVERAGE(O25:P25) -> 1.35 | T40: =_xlfn.STDEV.S(O25:P25) -> 1.6263456 | U40: =AVERAGE( _xlfn.XLOOKUP(TextureCal[[#This Row],[Texture]], SoilSpec[Texture], SoilSpec[Sand_Min]), _xlfn.XLOOKUP(TextureCal[[#This Row],[Texture]], SoilSpec[Texture], SoilSpec[Sand_Max]) ) -> 80 | V40: {=IFERROR(_xlfn.STDEV.S(_xlfn._xlws.FILTER(Soil_Samples[Sand], Soil_Samples[Texture]=TextureCal[[#This Row],[Texture]])),0)} -> 8.4852814 | W40: =AVERAGE( _xlfn.XLOOKUP(TextureCal[[#This Row],[Texture]], SoilSpec[Texture], SoilSpec[Silt_Min]), _xlfn.XLOOKUP(TextureCal[[#This Row],[Texture]], SoilSpec[Texture], SoilSpec[Silt_Max]) ) -> 12.5 | X40: {=IFERROR(_xlfn.STDEV.S(_xlfn._xlws.FILTER(Soil_Samples[Silt], Soil_Samples[Texture]=TextureCal[[#This Row],[Texture]])),0)} -> 8.4852814 | Y40: =AVERAGE( _xlfn.XLOOKUP(TextureCal[[#This Row],[Texture]], SoilSpec[Texture], SoilSpec[Clay_Min]), _xlfn.XLOOKUP(TextureCal[[#This Row],[Texture]], SoilSpec[Texture], SoilSpec[Clay_Max]) ) -> 7.5 | Z40: {=IFERROR(_xlfn.STDEV.S(_xlfn._xlws.FILTER(Soil_Samples[Clay], Soil_Samples[Texture]=TextureCal[[#This Row],[Texture]])),0)} -> 0 | AA40: {=_xlfn.LET( _xlpm.vals, _xlfn.HSTACK( $C$72, $C$73, $C$74, $C$80, pH, $C$76, $C$75, $C$79, $C$77 ), _xlpm.means, _xlfn.HSTACK( TextureCal[[#This Row],[N_Mean]], TextureCal[[#This Row],[P_Mean]], TextureCal[[#This Row],[K_Mean]], TextureCal[[#This Row],[EC_Mean]], TextureCal[[#This Row],[pH_Mean]], TextureCal[[#This Row],[Moisture_Mean]], TextureCal[[#This Row],[Temp_Mean]], TextureCal[[#This Row],[TF_Center]], TextureCal[[#This Row],[OM_Mean]] ), _xlpm.stds, _xlfn.HSTACK( TextureCal[[#This Row],[N_StdDev]], TextureCal[[#This Row],[P_StdDev]], TextureCal[[#This Row],[K_StdDev]], TextureCal[[#This Row],[EC_StdDev]], TextureCal[[#This Row],[pH_StdDev]], TextureCal[[#This Row],[Moisture_StdDev]], TextureCal[[#This Row],[Temp_StdDev]], TextureCal[[#This Row],[TF_StdDev]], TextureCal[[#This Row],[OM_StdDev]] ), SQRT(SUM(((_xlpm.vals - _xlpm.means) / _xlpm.stds)^2)) )} -> 10.577853 | AB40: =1 - ( TextureCal[[#This Row],[Euclidean Distance]] - MIN(TextureCal[Euclidean Distance]) ) / ( MAX(TextureCal[Euclidean Distance]) - MIN(TextureCal[Euclidean Distance]) ) -> 0.9177836 | AC40: {=_xlfn.LET( _xlpm.vals, _xlfn.HSTACK($C$72,$C$73,$C$74,$C$80,$C$81,$C$76,$C$77,$C$79,$C$75), _xlpm.mins, _xlfn.HSTACK(SoilSpec[N_Min],SoilSpec[P_Min],SoilSpec[K_Min], SoilSpec[EC_Min],SoilSpec[pH_Min],SoilSpec[Moisture_Min], SoilSpec[OM_Min],SoilSpec[TF_Min],SoilSpec[SoilTemp_Min]), _xlpm.maxs, _xlfn.HSTACK(SoilSpec[N_Max],SoilSpec[P_Max],SoilSpec[K_Max], SoilSpec[EC_Max],SoilSpec[pH_Max],SoilSpec[Moisture_Max], SoilSpec[OM_Max],SoilSpec[TF_Max],SoilSpec[SoilTemp_Max]), _xlpm.idx, ROW()-ROW(TextureCal[#Headers]), SUM( (_xlpm.vals >= INDEX(_xlpm.mins, _xlpm.idx)) * (_xlpm.vals <= INDEX(_xlpm.maxs, _xlpm.idx)) ) )} -> 6 | AD40: =1 - ( TextureCal[[#This Row],[Euclidean Distance]] - MIN(TextureCal[Euclidean Distance]) ) / ( MAX(TextureCal[Euclidean Distance]) - MIN(TextureCal[Euclidean Distance]) ) -> 0.9177836 | AE40: =(TextureCal[[#This Row],[BandScore]] / 9) * 0.6 + TextureCal[[#This Row],[NormDist]] * 0.4 -> 0.76711344
B41: Sandy Loam | C41: =(C26+D26)/2 -> 13 | D41: =(D26-C26)/6 -> 2.3333333 | E41: =(E26+F26)/2 -> 12 | F41: =(F26-E26)/6 -> 2.6666667 | G41: =(G26+H26)/2 -> 120 | H41: =(H26-G26)/6 -> 26.666667 | I41: =(I26+J26)/2 -> 1.3 | J41: =(J26-I26)/6 -> 0.4 | K41: =(K26+L26)/2 -> 7 | L41: =(L26-K26)/6 -> 0.5 | M41: =(M26+N26)/2 -> 17.5 | N41: =(N26-M26)/6 -> 2.5 | O41: =(AA26+AB26)/2 -> 31 | P41: =(AB26-AA26)/6 -> 2.3333333 | Q41: =(S26+T26)/2 -> 0.2 | R41: =(T26-S26)/4 -> 0.01 | S41: =AVERAGE(O26:P26) -> 1.65 | T41: =_xlfn.STDEV.S(O26:P26) -> 1.9091883 | U41: =AVERAGE( _xlfn.XLOOKUP(TextureCal[[#This Row],[Texture]], SoilSpec[Texture], SoilSpec[Sand_Min]), _xlfn.XLOOKUP(TextureCal[[#This Row],[Texture]], SoilSpec[Texture], SoilSpec[Sand_Max]) ) -> 64 | V41: {=IFERROR(_xlfn.STDEV.S(_xlfn._xlws.FILTER(Soil_Samples[Sand], Soil_Samples[Texture]=TextureCal[[#This Row],[Texture]])),0)} -> 4.4153412 | W41: =AVERAGE( _xlfn.XLOOKUP(TextureCal[[#This Row],[Texture]], SoilSpec[Texture], SoilSpec[Silt_Min]), _xlfn.XLOOKUP(TextureCal[[#This Row],[Texture]], SoilSpec[Texture], SoilSpec[Silt_Max]) ) -> 25 | X41: {=IFERROR(_xlfn.STDEV.S(_xlfn._xlws.FILTER(Soil_Samples[Silt], Soil_Samples[Texture]=TextureCal[[#This Row],[Texture]])),0)} -> 4.2333708 | Y41: =AVERAGE( _xlfn.XLOOKUP(TextureCal[[#This Row],[Texture]], SoilSpec[Texture], SoilSpec[Clay_Min]), _xlfn.XLOOKUP(TextureCal[[#This Row],[Texture]], SoilSpec[Texture], SoilSpec[Clay_Max]) ) -> 10 | Z41: {=IFERROR(_xlfn.STDEV.S(_xlfn._xlws.FILTER(Soil_Samples[Clay], Soil_Samples[Texture]=TextureCal[[#This Row],[Texture]])),0)} -> 2.8347335 | AA41: {=_xlfn.LET( _xlpm.vals, _xlfn.HSTACK( $C$72, $C$73, $C$74, $C$80, pH, $C$76, $C$75, $C$79, $C$77 ), _xlpm.means, _xlfn.HSTACK( TextureCal[[#This Row],[N_Mean]], TextureCal[[#This Row],[P_Mean]], TextureCal[[#This Row],[K_Mean]], TextureCal[[#This Row],[EC_Mean]], TextureCal[[#This Row],[pH_Mean]], TextureCal[[#This Row],[Moisture_Mean]], TextureCal[[#This Row],[Temp_Mean]], TextureCal[[#This Row],[TF_Center]], TextureCal[[#This Row],[OM_Mean]] ), _xlpm.stds, _xlfn.HSTACK( TextureCal[[#This Row],[N_StdDev]], TextureCal[[#This Row],[P_StdDev]], TextureCal[[#This Row],[K_StdDev]], TextureCal[[#This Row],[EC_StdDev]], TextureCal[[#This Row],[pH_StdDev]], TextureCal[[#This Row],[Moisture_StdDev]], TextureCal[[#This Row],[Temp_StdDev]], TextureCal[[#This Row],[TF_StdDev]], TextureCal[[#This Row],[OM_StdDev]] ), SQRT(SUM(((_xlpm.vals - _xlpm.means) / _xlpm.stds)^2)) )} -> 15.6735 | AB41: =1 - ( TextureCal[[#This Row],[Euclidean Distance]] - MIN(TextureCal[Euclidean Distance]) ) / ( MAX(TextureCal[Euclidean Distance]) - MIN(TextureCal[Euclidean Distance]) ) -> 0.7525704 | AC41: {=_xlfn.LET( _xlpm.vals, _xlfn.HSTACK($C$72,$C$73,$C$74,$C$80,$C$81,$C$76,$C$77,$C$79,$C$75), _xlpm.mins, _xlfn.HSTACK(SoilSpec[N_Min],SoilSpec[P_Min],SoilSpec[K_Min], SoilSpec[EC_Min],SoilSpec[pH_Min],SoilSpec[Moisture_Min], SoilSpec[OM_Min],SoilSpec[TF_Min],SoilSpec[SoilTemp_Min]), _xlpm.maxs, _xlfn.HSTACK(SoilSpec[N_Max],SoilSpec[P_Max],SoilSpec[K_Max], SoilSpec[EC_Max],SoilSpec[pH_Max],SoilSpec[Moisture_Max], SoilSpec[OM_Max],SoilSpec[TF_Max],SoilSpec[SoilTemp_Max]), _xlpm.idx, ROW()-ROW(TextureCal[#Headers]), SUM( (_xlpm.vals >= INDEX(_xlpm.mins, _xlpm.idx)) * (_xlpm.vals <= INDEX(_xlpm.maxs, _xlpm.idx)) ) )} -> 6 | AD41: =1 - ( TextureCal[[#This Row],[Euclidean Distance]] - MIN(TextureCal[Euclidean Distance]) ) / ( MAX(TextureCal[Euclidean Distance]) - MIN(TextureCal[Euclidean Distance]) ) -> 0.7525704 | AE41: =(TextureCal[[#This Row],[BandScore]] / 9) * 0.6 + TextureCal[[#This Row],[NormDist]] * 0.4 -> 0.70102816
B42: Loam | C42: =(C27+D27)/2 -> 16.5 | D42: =(D27-C27)/6 -> 2.8333333 | E42: =(E27+F27)/2 -> 15 | F42: =(F27-E27)/6 -> 3.3333333 | G42: =(G27+H27)/2 -> 155 | H42: =(H27-G27)/6 -> 31.666667 | I42: =(I27+J27)/2 -> 1.55 | J42: =(J27-I27)/6 -> 0.48333333 | K42: =(K27+L27)/2 -> 6.85 | L42: =(L27-K27)/6 -> 0.45 | M42: =(M27+N27)/2 -> 22.5 | N42: =(N27-M27)/6 -> 2.5 | O42: =(AA27+AB27)/2 -> 31 | P42: =(AB27-AA27)/6 -> 2.3333333 | Q42: =(S27+T27)/2 -> 0.27 | R42: =(T27-S27)/4 -> 0.015 | S42: =AVERAGE(O27:P27) -> 2.25 | T42: =_xlfn.STDEV.S(O27:P27) -> 2.4748737 | U42: =AVERAGE( _xlfn.XLOOKUP(TextureCal[[#This Row],[Texture]], SoilSpec[Texture], SoilSpec[Sand_Min]), _xlfn.XLOOKUP(TextureCal[[#This Row],[Texture]], SoilSpec[Texture], SoilSpec[Sand_Max]) ) -> 37.5 | V42: {=IFERROR(_xlfn.STDEV.S(_xlfn._xlws.FILTER(Soil_Samples[Sand], Soil_Samples[Texture]=TextureCal[[#This Row],[Texture]])),0)} -> 19.425572 | W42: =AVERAGE( _xlfn.XLOOKUP(TextureCal[[#This Row],[Texture]], SoilSpec[Texture], SoilSpec[Silt_Min]), _xlfn.XLOOKUP(TextureCal[[#This Row],[Texture]], SoilSpec[Texture], SoilSpec[Silt_Max]) ) -> 39 | X42: {=IFERROR(_xlfn.STDEV.S(_xlfn._xlws.FILTER(Soil_Samples[Silt], Soil_Samples[Texture]=TextureCal[[#This Row],[Texture]])),0)} -> 20.186815 | Y42: =AVERAGE( _xlfn.XLOOKUP(TextureCal[[#This Row],[Texture]], SoilSpec[Texture], SoilSpec[Clay_Min]), _xlfn.XLOOKUP(TextureCal[[#This Row],[Texture]], SoilSpec[Texture], SoilSpec[Clay_Max]) ) -> 17 | Z42: {=IFERROR(_xlfn.STDEV.S(_xlfn._xlws.FILTER(Soil_Samples[Clay], Soil_Samples[Texture]=TextureCal[[#This Row],[Texture]])),0)} -> 10.328228 | AA42: {=_xlfn.LET( _xlpm.vals, _xlfn.HSTACK( $C$72, $C$73, $C$74, $C$80, pH, $C$76, $C$75, $C$79, $C$77 ), _xlpm.means, _xlfn.HSTACK( TextureCal[[#This Row],[N_Mean]], TextureCal[[#This Row],[P_Mean]], TextureCal[[#This Row],[K_Mean]], TextureCal[[#This Row],[EC_Mean]], TextureCal[[#This Row],[pH_Mean]], TextureCal[[#This Row],[Moisture_Mean]], TextureCal[[#This Row],[Temp_Mean]], TextureCal[[#This Row],[TF_Center]], TextureCal[[#This Row],[OM_Mean]] ), _xlpm.stds, _xlfn.HSTACK( TextureCal[[#This Row],[N_StdDev]], TextureCal[[#This Row],[P_StdDev]], TextureCal[[#This Row],[K_StdDev]], TextureCal[[#This Row],[EC_StdDev]], TextureCal[[#This Row],[pH_StdDev]], TextureCal[[#This Row],[Moisture_StdDev]], TextureCal[[#This Row],[Temp_StdDev]], TextureCal[[#This Row],[TF_StdDev]], TextureCal[[#This Row],[OM_StdDev]] ), SQRT(SUM(((_xlpm.vals - _xlpm.means) / _xlpm.stds)^2)) )} -> 16.572822 | AB42: =1 - ( TextureCal[[#This Row],[Euclidean Distance]] - MIN(TextureCal[Euclidean Distance]) ) / ( MAX(TextureCal[Euclidean Distance]) - MIN(TextureCal[Euclidean Distance]) ) -> 0.72341221 | AC42: {=_xlfn.LET( _xlpm.vals, _xlfn.HSTACK($C$72,$C$73,$C$74,$C$80,$C$81,$C$76,$C$77,$C$79,$C$75), _xlpm.mins, _xlfn.HSTACK(SoilSpec[N_Min],SoilSpec[P_Min],SoilSpec[K_Min], SoilSpec[EC_Min],SoilSpec[pH_Min],SoilSpec[Moisture_Min], SoilSpec[OM_Min],SoilSpec[TF_Min],SoilSpec[SoilTemp_Min]), _xlpm.maxs, _xlfn.HSTACK(SoilSpec[N_Max],SoilSpec[P_Max],SoilSpec[K_Max], SoilSpec[EC_Max],SoilSpec[pH_Max],SoilSpec[Moisture_Max], SoilSpec[OM_Max],SoilSpec[TF_Max],SoilSpec[SoilTemp_Max]), _xlpm.idx, ROW()-ROW(TextureCal[#Headers]), SUM( (_xlpm.vals >= INDEX(_xlpm.mins, _xlpm.idx)) * (_xlpm.vals <= INDEX(_xlpm.maxs, _xlpm.idx)) ) )} -> 5 | AD42: =1 - ( TextureCal[[#This Row],[Euclidean Distance]] - MIN(TextureCal[Euclidean Distance]) ) / ( MAX(TextureCal[Euclidean Distance]) - MIN(TextureCal[Euclidean Distance]) ) -> 0.72341221 | AE42: =(TextureCal[[#This Row],[BandScore]] / 9) * 0.6 + TextureCal[[#This Row],[NormDist]] * 0.4 -> 0.62269822
B43: Silt Loam | C43: =(C28+D28)/2 -> 20 | D43: =(D28-C28)/6 -> 3.3333333 | E43: =(E28+F28)/2 -> 18 | F43: =(F28-E28)/6 -> 4 | G43: =(G28+H28)/2 -> 185 | H43: =(H28-G28)/6 -> 38.333333 | I43: =(I28+J28)/2 -> 1.55 | J43: =(J28-I28)/6 -> 0.48333333 | K43: =(K28+L28)/2 -> 6.75 | L43: =(L28-K28)/6 -> 0.41666667 | M43: =(M28+N28)/2 -> 27.5 | N43: =(N28-M28)/6 -> 2.5 | O43: =(AA28+AB28)/2 -> 31 | P43: =(AB28-AA28)/6 -> 2.3333333 | Q43: =(S28+T28)/2 -> 0.34 | R43: =(T28-S28)/4 -> 0.02 | S43: =AVERAGE(O28:P28) -> 2.55 | T43: =_xlfn.STDEV.S(O28:P28) -> 2.7577164 | U43: =AVERAGE( _xlfn.XLOOKUP(TextureCal[[#This Row],[Texture]], SoilSpec[Texture], SoilSpec[Sand_Min]), _xlfn.XLOOKUP(TextureCal[[#This Row],[Texture]], SoilSpec[Texture], SoilSpec[Sand_Max]) ) -> 25 | V43: {=IFERROR(_xlfn.STDEV.S(_xlfn._xlws.FILTER(Soil_Samples[Sand], Soil_Samples[Texture]=TextureCal[[#This Row],[Texture]])),0)} -> 7.5472 | W43: =AVERAGE( _xlfn.XLOOKUP(TextureCal[[#This Row],[Texture]], SoilSpec[Texture], SoilSpec[Silt_Min]), _xlfn.XLOOKUP(TextureCal[[#This Row],[Texture]], SoilSpec[Texture], SoilSpec[Silt_Max]) ) -> 69 | X43: {=IFERROR(_xlfn.STDEV.S(_xlfn._xlws.FILTER(Soil_Samples[Silt], Soil_Samples[Texture]=TextureCal[[#This Row],[Texture]])),0)} -> 6.246211 | Y43: =AVERAGE( _xlfn.XLOOKUP(TextureCal[[#This Row],[Texture]], SoilSpec[Texture], SoilSpec[Clay_Min]), _xlfn.XLOOKUP(TextureCal[[#This Row],[Texture]], SoilSpec[Texture], SoilSpec[Clay_Max]) ) -> 13.5 | Z43: {=IFERROR(_xlfn.STDEV.S(_xlfn._xlws.FILTER(Soil_Samples[Clay], Soil_Samples[Texture]=TextureCal[[#This Row],[Texture]])),0)} -> 4.1912156 | AA43: {=_xlfn.LET( _xlpm.vals, _xlfn.HSTACK( $C$72, $C$73, $C$74, $C$80, pH, $C$76, $C$75, $C$79, $C$77 ), _xlpm.means, _xlfn.HSTACK( TextureCal[[#This Row],[N_Mean]], TextureCal[[#This Row],[P_Mean]], TextureCal[[#This Row],[K_Mean]], TextureCal[[#This Row],[EC_Mean]], TextureCal[[#This Row],[pH_Mean]], TextureCal[[#This Row],[Moisture_Mean]], TextureCal[[#This Row],[Temp_Mean]], TextureCal[[#This Row],[TF_Center]], TextureCal[[#This Row],[OM_Mean]] ), _xlpm.stds, _xlfn.HSTACK( TextureCal[[#This Row],[N_StdDev]], TextureCal[[#This Row],[P_StdDev]], TextureCal[[#This Row],[K_StdDev]], TextureCal[[#This Row],[EC_StdDev]], TextureCal[[#This Row],[pH_StdDev]], TextureCal[[#This Row],[Moisture_StdDev]], TextureCal[[#This Row],[Temp_StdDev]], TextureCal[[#This Row],[TF_StdDev]], TextureCal[[#This Row],[OM_StdDev]] ), SQRT(SUM(((_xlpm.vals - _xlpm.means) / _xlpm.stds)^2)) )} -> 17.389666 | AB43: =1 - ( TextureCal[[#This Row],[Euclidean Distance]] - MIN(TextureCal[Euclidean Distance]) ) / ( MAX(TextureCal[Euclidean Distance]) - MIN(TextureCal[Euclidean Distance]) ) -> 0.69692815 | AC43: {=_xlfn.LET( _xlpm.vals, _xlfn.HSTACK($C$72,$C$73,$C$74,$C$80,$C$81,$C$76,$C$77,$C$79,$C$75), _xlpm.mins, _xlfn.HSTACK(SoilSpec[N_Min],SoilSpec[P_Min],SoilSpec[K_Min], SoilSpec[EC_Min],SoilSpec[pH_Min],SoilSpec[Moisture_Min], SoilSpec[OM_Min],SoilSpec[TF_Min],SoilSpec[SoilTemp_Min]), _xlpm.maxs, _xlfn.HSTACK(SoilSpec[N_Max],SoilSpec[P_Max],SoilSpec[K_Max], SoilSpec[EC_Max],SoilSpec[pH_Max],SoilSpec[Moisture_Max], SoilSpec[OM_Max],SoilSpec[TF_Max],SoilSpec[SoilTemp_Max]), _xlpm.idx, ROW()-ROW(TextureCal[#Headers]), SUM( (_xlpm.vals >= INDEX(_xlpm.mins, _xlpm.idx)) * (_xlpm.vals <= INDEX(_xlpm.maxs, _xlpm.idx)) ) )} -> 3 | AD43: =1 - ( TextureCal[[#This Row],[Euclidean Distance]] - MIN(TextureCal[Euclidean Distance]) ) / ( MAX(TextureCal[Euclidean Distance]) - MIN(TextureCal[Euclidean Distance]) ) -> 0.69692815 | AE43: =(TextureCal[[#This Row],[BandScore]] / 9) * 0.6 + TextureCal[[#This Row],[NormDist]] * 0.4 -> 0.47877126
